2021-02-05 16:22:09,030 ERROR: Exception on /reset_password_request [POST] [in c:\users\user\desktop\microblog\myenv\lib\site-packages\flask\app.py:1892]
Traceback (most recent call last):
  File "c:\users\user\desktop\microblog\myenv\lib\site-packages\flask\app.py", line 2447, in wsgi_app
    response = self.full_dispatch_request()
  File "c:\users\user\desktop\microblog\myenv\lib\site-packages\flask\app.py", line 1952, in full_dispatch_request
    rv = self.handle_user_exception(e)
  File "c:\users\user\desktop\microblog\myenv\lib\site-packages\flask\app.py", line 1821, in handle_user_exception
    reraise(exc_type, exc_value, tb)
  File "c:\users\user\desktop\microblog\myenv\lib\site-packages\flask\_compat.py", line 39, in reraise
    raise value
  File "c:\users\user\desktop\microblog\myenv\lib\site-packages\flask\app.py", line 1950, in full_dispatch_request
    rv = self.dispatch_request()
  File "c:\users\user\desktop\microblog\myenv\lib\site-packages\flask\app.py", line 1936, in dispatch_request
    return self.view_functions[rule.endpoint](**req.view_args)
  File "C:\Users\User\Desktop\microblog\app\routes.py", line 165, in reset_password_request
    send_password_reset_email(user)
  File "C:\Users\User\Desktop\microblog\app\email.py", line 20, in send_password_reset_email
    token = user.get_reset_password_token()
  File "C:\Users\User\Desktop\microblog\app\models.py", line 66, in get_reset_password_token
    app.config['SECRET_KEY'], algorithm='HS256').decode('utf-8')
AttributeError: 'str' object has no attribute 'decode'
2021-02-06 14:28:34,059 INFO: Microblog startup [in C:\Users\User\Desktop\microblog\app\__init__.py:51]
2021-02-06 14:28:38,253 ERROR: Exception on / [GET] [in c:\users\user\desktop\microblog\myenv\lib\site-packages\flask\app.py:1892]
Traceback (most recent call last):
  File "c:\users\user\desktop\microblog\myenv\lib\site-packages\flask\app.py", line 2447, in wsgi_app
    response = self.full_dispatch_request()
  File "c:\users\user\desktop\microblog\myenv\lib\site-packages\flask\app.py", line 1952, in full_dispatch_request
    rv = self.handle_user_exception(e)
  File "c:\users\user\desktop\microblog\myenv\lib\site-packages\flask\app.py", line 1821, in handle_user_exception
    reraise(exc_type, exc_value, tb)
  File "c:\users\user\desktop\microblog\myenv\lib\site-packages\flask\_compat.py", line 39, in reraise
    raise value
  File "c:\users\user\desktop\microblog\myenv\lib\site-packages\flask\app.py", line 1950, in full_dispatch_request
    rv = self.dispatch_request()
  File "c:\users\user\desktop\microblog\myenv\lib\site-packages\flask\app.py", line 1936, in dispatch_request
    return self.view_functions[rule.endpoint](**req.view_args)
  File "C:\Users\User\Desktop\microblog\app\routes.py", line 29, in index
    posts = current_user.followed_posts().paginate(
  File "c:\users\user\desktop\microblog\myenv\lib\site-packages\werkzeug\local.py", line 347, in __getattr__
    return getattr(self._get_current_object(), name)
AttributeError: 'AnonymousUserMixin' object has no attribute 'followed_posts'
2021-02-06 14:31:44,161 INFO: Microblog startup [in C:\Users\User\Desktop\microblog\app\__init__.py:51]
2021-02-06 14:31:48,168 ERROR: Exception on / [GET] [in c:\users\user\desktop\microblog\myenv\lib\site-packages\flask\app.py:1892]
Traceback (most recent call last):
  File "c:\users\user\desktop\microblog\myenv\lib\site-packages\flask\app.py", line 2447, in wsgi_app
    response = self.full_dispatch_request()
  File "c:\users\user\desktop\microblog\myenv\lib\site-packages\flask\app.py", line 1952, in full_dispatch_request
    rv = self.handle_user_exception(e)
  File "c:\users\user\desktop\microblog\myenv\lib\site-packages\flask\app.py", line 1821, in handle_user_exception
    reraise(exc_type, exc_value, tb)
  File "c:\users\user\desktop\microblog\myenv\lib\site-packages\flask\_compat.py", line 39, in reraise
    raise value
  File "c:\users\user\desktop\microblog\myenv\lib\site-packages\flask\app.py", line 1950, in full_dispatch_request
    rv = self.dispatch_request()
  File "c:\users\user\desktop\microblog\myenv\lib\site-packages\flask\app.py", line 1936, in dispatch_request
    return self.view_functions[rule.endpoint](**req.view_args)
  File "C:\Users\User\Desktop\microblog\app\routes.py", line 29, in index
    posts = current_user.followed_posts().paginate(\
  File "c:\users\user\desktop\microblog\myenv\lib\site-packages\werkzeug\local.py", line 347, in __getattr__
    return getattr(self._get_current_object(), name)
AttributeError: 'AnonymousUserMixin' object has no attribute 'followed_posts'
2021-02-06 14:33:35,033 ERROR: Exception on /index [GET] [in c:\users\user\desktop\microblog\myenv\lib\site-packages\flask\app.py:1892]
Traceback (most recent call last):
  File "c:\users\user\desktop\microblog\myenv\lib\site-packages\flask\app.py", line 2447, in wsgi_app
    response = self.full_dispatch_request()
  File "c:\users\user\desktop\microblog\myenv\lib\site-packages\flask\app.py", line 1952, in full_dispatch_request
    rv = self.handle_user_exception(e)
  File "c:\users\user\desktop\microblog\myenv\lib\site-packages\flask\app.py", line 1821, in handle_user_exception
    reraise(exc_type, exc_value, tb)
  File "c:\users\user\desktop\microblog\myenv\lib\site-packages\flask\_compat.py", line 39, in reraise
    raise value
  File "c:\users\user\desktop\microblog\myenv\lib\site-packages\flask\app.py", line 1950, in full_dispatch_request
    rv = self.dispatch_request()
  File "c:\users\user\desktop\microblog\myenv\lib\site-packages\flask\app.py", line 1936, in dispatch_request
    return self.view_functions[rule.endpoint](**req.view_args)
  File "C:\Users\User\Desktop\microblog\app\routes.py", line 29, in index
    posts = current_user.followed_posts().paginate(\
  File "c:\users\user\desktop\microblog\myenv\lib\site-packages\werkzeug\local.py", line 347, in __getattr__
    return getattr(self._get_current_object(), name)
AttributeError: 'AnonymousUserMixin' object has no attribute 'followed_posts'
2021-02-06 14:34:15,250 INFO: Microblog startup [in C:\Users\User\Desktop\microblog\app\__init__.py:51]
2021-02-06 14:35:57,111 INFO: Microblog startup [in C:\Users\User\Desktop\microblog\app\__init__.py:51]
2021-02-06 14:36:15,835 ERROR: Exception on /index [GET] [in c:\users\user\desktop\microblog\myenv\lib\site-packages\flask\app.py:1892]
Traceback (most recent call last):
  File "c:\users\user\desktop\microblog\myenv\lib\site-packages\flask\app.py", line 2447, in wsgi_app
    response = self.full_dispatch_request()
  File "c:\users\user\desktop\microblog\myenv\lib\site-packages\flask\app.py", line 1952, in full_dispatch_request
    rv = self.handle_user_exception(e)
  File "c:\users\user\desktop\microblog\myenv\lib\site-packages\flask\app.py", line 1821, in handle_user_exception
    reraise(exc_type, exc_value, tb)
  File "c:\users\user\desktop\microblog\myenv\lib\site-packages\flask\_compat.py", line 39, in reraise
    raise value
  File "c:\users\user\desktop\microblog\myenv\lib\site-packages\flask\app.py", line 1950, in full_dispatch_request
    rv = self.dispatch_request()
  File "c:\users\user\desktop\microblog\myenv\lib\site-packages\flask\app.py", line 1936, in dispatch_request
    return self.view_functions[rule.endpoint](**req.view_args)
  File "C:\Users\User\Desktop\microblog\app\routes.py", line 29, in index
    posts = current_user.followed_posts().paginate(\
  File "c:\users\user\desktop\microblog\myenv\lib\site-packages\werkzeug\local.py", line 347, in __getattr__
    return getattr(self._get_current_object(), name)
AttributeError: 'AnonymousUserMixin' object has no attribute 'followed_posts'
2021-02-06 14:36:57,911 INFO: Microblog startup [in C:\Users\User\Desktop\microblog\app\__init__.py:51]
2021-02-06 14:37:01,059 ERROR: Exception on /index [GET] [in c:\users\user\desktop\microblog\myenv\lib\site-packages\flask\app.py:1892]
Traceback (most recent call last):
  File "c:\users\user\desktop\microblog\myenv\lib\site-packages\flask\app.py", line 2447, in wsgi_app
    response = self.full_dispatch_request()
  File "c:\users\user\desktop\microblog\myenv\lib\site-packages\flask\app.py", line 1952, in full_dispatch_request
    rv = self.handle_user_exception(e)
  File "c:\users\user\desktop\microblog\myenv\lib\site-packages\flask\app.py", line 1821, in handle_user_exception
    reraise(exc_type, exc_value, tb)
  File "c:\users\user\desktop\microblog\myenv\lib\site-packages\flask\_compat.py", line 39, in reraise
    raise value
  File "c:\users\user\desktop\microblog\myenv\lib\site-packages\flask\app.py", line 1950, in full_dispatch_request
    rv = self.dispatch_request()
  File "c:\users\user\desktop\microblog\myenv\lib\site-packages\flask\app.py", line 1936, in dispatch_request
    return self.view_functions[rule.endpoint](**req.view_args)
  File "C:\Users\User\Desktop\microblog\app\routes.py", line 29, in index
    posts = current_user.followed_posts().paginate(\
  File "c:\users\user\desktop\microblog\myenv\lib\site-packages\werkzeug\local.py", line 347, in __getattr__
    return getattr(self._get_current_object(), name)
AttributeError: 'AnonymousUserMixin' object has no attribute 'followed_posts'
2021-02-06 14:40:32,762 INFO: Microblog startup [in C:\Users\User\Desktop\microblog\app\__init__.py:51]
