2021-02-05 15:33:46,967 ERROR: Exception on /index [GET] [in c:\users\user\desktop\microblog\myenv\lib\site-packages\flask\app.py:1892]
Traceback (most recent call last):
  File "c:\users\user\desktop\microblog\myenv\lib\site-packages\flask\app.py", line 2447, in wsgi_app
    response = self.full_dispatch_request()
  File "c:\users\user\desktop\microblog\myenv\lib\site-packages\flask\app.py", line 1952, in full_dispatch_request
    rv = self.handle_user_exception(e)
  File "c:\users\user\desktop\microblog\myenv\lib\site-packages\flask\app.py", line 1821, in handle_user_exception
    reraise(exc_type, exc_value, tb)
  File "c:\users\user\desktop\microblog\myenv\lib\site-packages\flask\_compat.py", line 39, in reraise
    raise value
  File "c:\users\user\desktop\microblog\myenv\lib\site-packages\flask\app.py", line 1950, in full_dispatch_request
    rv = self.dispatch_request()
  File "c:\users\user\desktop\microblog\myenv\lib\site-packages\flask\app.py", line 1936, in dispatch_request
    return self.view_functions[rule.endpoint](**req.view_args)
  File "C:\Users\User\Desktop\microblog\app\routes.py", line 27, in index
    posts = current_user.followed_posts().paginate(page, app.config['POSTS_PER_PAGE'], False)
  File "c:\users\user\desktop\microblog\myenv\lib\site-packages\werkzeug\local.py", line 347, in __getattr__
    return getattr(self._get_current_object(), name)
AttributeError: 'AnonymousUserMixin' object has no attribute 'followed_posts'
2021-02-05 15:33:50,732 ERROR: Exception on /index [GET] [in c:\users\user\desktop\microblog\myenv\lib\site-packages\flask\app.py:1892]
Traceback (most recent call last):
  File "c:\users\user\desktop\microblog\myenv\lib\site-packages\flask\app.py", line 2447, in wsgi_app
    response = self.full_dispatch_request()
  File "c:\users\user\desktop\microblog\myenv\lib\site-packages\flask\app.py", line 1952, in full_dispatch_request
    rv = self.handle_user_exception(e)
  File "c:\users\user\desktop\microblog\myenv\lib\site-packages\flask\app.py", line 1821, in handle_user_exception
    reraise(exc_type, exc_value, tb)
  File "c:\users\user\desktop\microblog\myenv\lib\site-packages\flask\_compat.py", line 39, in reraise
    raise value
  File "c:\users\user\desktop\microblog\myenv\lib\site-packages\flask\app.py", line 1950, in full_dispatch_request
    rv = self.dispatch_request()
  File "c:\users\user\desktop\microblog\myenv\lib\site-packages\flask\app.py", line 1936, in dispatch_request
    return self.view_functions[rule.endpoint](**req.view_args)
  File "C:\Users\User\Desktop\microblog\app\routes.py", line 27, in index
    posts = current_user.followed_posts().paginate(page, app.config['POSTS_PER_PAGE'], False)
  File "c:\users\user\desktop\microblog\myenv\lib\site-packages\werkzeug\local.py", line 347, in __getattr__
    return getattr(self._get_current_object(), name)
AttributeError: 'AnonymousUserMixin' object has no attribute 'followed_posts'
2021-02-05 15:34:32,404 ERROR: Exception on /explore [GET] [in c:\users\user\desktop\microblog\myenv\lib\site-packages\flask\app.py:1892]
Traceback (most recent call last):
  File "c:\users\user\desktop\microblog\myenv\lib\site-packages\flask\app.py", line 2447, in wsgi_app
    response = self.full_dispatch_request()
  File "c:\users\user\desktop\microblog\myenv\lib\site-packages\flask\app.py", line 1952, in full_dispatch_request
    rv = self.handle_user_exception(e)
  File "c:\users\user\desktop\microblog\myenv\lib\site-packages\flask\app.py", line 1821, in handle_user_exception
    reraise(exc_type, exc_value, tb)
  File "c:\users\user\desktop\microblog\myenv\lib\site-packages\flask\_compat.py", line 39, in reraise
    raise value
  File "c:\users\user\desktop\microblog\myenv\lib\site-packages\flask\app.py", line 1950, in full_dispatch_request
    rv = self.dispatch_request()
  File "c:\users\user\desktop\microblog\myenv\lib\site-packages\flask\app.py", line 1936, in dispatch_request
    return self.view_functions[rule.endpoint](**req.view_args)
  File "c:\users\user\desktop\microblog\myenv\lib\site-packages\flask_login\utils.py", line 272, in decorated_view
    return func(*args, **kwargs)
  File "C:\Users\User\Desktop\microblog\app\routes.py", line 44, in explore
    return render_template('index.html', title='Explore', posts=posts, next_url=next_url, prev_url=prev_url)
  File "c:\users\user\desktop\microblog\myenv\lib\site-packages\flask\templating.py", line 140, in render_template
    ctx.app,
  File "c:\users\user\desktop\microblog\myenv\lib\site-packages\flask\templating.py", line 120, in _render
    rv = template.render(context)
  File "c:\users\user\desktop\microblog\myenv\lib\site-packages\jinja2\environment.py", line 1090, in render
    self.environment.handle_exception()
  File "c:\users\user\desktop\microblog\myenv\lib\site-packages\jinja2\environment.py", line 832, in handle_exception
    reraise(*rewrite_traceback_stack(source=source))
  File "c:\users\user\desktop\microblog\myenv\lib\site-packages\jinja2\_compat.py", line 28, in reraise
    raise value.with_traceback(tb)
  File "C:\Users\User\Desktop\microblog\app\templates\index.html", line 1, in top-level template code
    {% extends "base.html" %}
  File "C:\Users\User\Desktop\microblog\app\templates\base.html", line 30, in top-level template code
    {% block content %}{% endblock content %}
  File "C:\Users\User\Desktop\microblog\app\templates\index.html", line 18, in block "content"
    {% for post in posts %}
TypeError: 'Pagination' object is not iterable
2021-02-05 15:42:01,878 INFO: Microblog startup [in C:\Users\User\Desktop\microblog\app\__init__.py:45]
2021-02-05 15:42:07,242 ERROR: Exception on /index [GET] [in c:\users\user\desktop\microblog\myenv\lib\site-packages\flask\app.py:1892]
Traceback (most recent call last):
  File "c:\users\user\desktop\microblog\myenv\lib\site-packages\flask\app.py", line 2447, in wsgi_app
    response = self.full_dispatch_request()
  File "c:\users\user\desktop\microblog\myenv\lib\site-packages\flask\app.py", line 1952, in full_dispatch_request
    rv = self.handle_user_exception(e)
  File "c:\users\user\desktop\microblog\myenv\lib\site-packages\flask\app.py", line 1821, in handle_user_exception
    reraise(exc_type, exc_value, tb)
  File "c:\users\user\desktop\microblog\myenv\lib\site-packages\flask\_compat.py", line 39, in reraise
    raise value
  File "c:\users\user\desktop\microblog\myenv\lib\site-packages\flask\app.py", line 1950, in full_dispatch_request
    rv = self.dispatch_request()
  File "c:\users\user\desktop\microblog\myenv\lib\site-packages\flask\app.py", line 1936, in dispatch_request
    return self.view_functions[rule.endpoint](**req.view_args)
  File "C:\Users\User\Desktop\microblog\app\routes.py", line 32, in index
    return render_template('index.html', title='Index', form=form, posts=posts, next_url=next_url, prev_url=prev_url)
  File "c:\users\user\desktop\microblog\myenv\lib\site-packages\flask\templating.py", line 140, in render_template
    ctx.app,
  File "c:\users\user\desktop\microblog\myenv\lib\site-packages\flask\templating.py", line 120, in _render
    rv = template.render(context)
  File "c:\users\user\desktop\microblog\myenv\lib\site-packages\jinja2\environment.py", line 1090, in render
    self.environment.handle_exception()
  File "c:\users\user\desktop\microblog\myenv\lib\site-packages\jinja2\environment.py", line 832, in handle_exception
    reraise(*rewrite_traceback_stack(source=source))
  File "c:\users\user\desktop\microblog\myenv\lib\site-packages\jinja2\_compat.py", line 28, in reraise
    raise value.with_traceback(tb)
  File "C:\Users\User\Desktop\microblog\app\templates\index.html", line 1, in top-level template code
    {% extends "base.html" %}
  File "C:\Users\User\Desktop\microblog\app\templates\base.html", line 30, in top-level template code
    {% block content %}{% endblock content %}
  File "C:\Users\User\Desktop\microblog\app\templates\index.html", line 18, in block "content"
    {% for post in posts %}
TypeError: 'Pagination' object is not iterable
2021-02-05 15:44:27,447 INFO: Microblog startup [in C:\Users\User\Desktop\microblog\app\__init__.py:45]
