2021-02-06 14:40:37,505 ERROR: Exception on /index [GET] [in c:\users\user\desktop\microblog\myenv\lib\site-packages\flask\app.py:1892]
Traceback (most recent call last):
  File "c:\users\user\desktop\microblog\myenv\lib\site-packages\flask\app.py", line 2447, in wsgi_app
    response = self.full_dispatch_request()
  File "c:\users\user\desktop\microblog\myenv\lib\site-packages\flask\app.py", line 1952, in full_dispatch_request
    rv = self.handle_user_exception(e)
  File "c:\users\user\desktop\microblog\myenv\lib\site-packages\flask\app.py", line 1821, in handle_user_exception
    reraise(exc_type, exc_value, tb)
  File "c:\users\user\desktop\microblog\myenv\lib\site-packages\flask\_compat.py", line 39, in reraise
    raise value
  File "c:\users\user\desktop\microblog\myenv\lib\site-packages\flask\app.py", line 1950, in full_dispatch_request
    rv = self.dispatch_request()
  File "c:\users\user\desktop\microblog\myenv\lib\site-packages\flask\app.py", line 1936, in dispatch_request
    return self.view_functions[rule.endpoint](**req.view_args)
  File "C:\Users\User\Desktop\microblog\app\routes.py", line 28, in index
    posts = current_user.followed_posts().paginate(page, app.config['POSTS_PER_PAGE'], False)
  File "c:\users\user\desktop\microblog\myenv\lib\site-packages\werkzeug\local.py", line 347, in __getattr__
    return getattr(self._get_current_object(), name)
AttributeError: 'AnonymousUserMixin' object has no attribute 'followed_posts'
2021-02-06 14:50:02,349 INFO: Microblog startup [in C:\Users\User\Desktop\microblog\app\__init__.py:51]
2021-02-06 14:50:06,310 ERROR: Exception on /index [GET] [in c:\users\user\desktop\microblog\myenv\lib\site-packages\flask\app.py:1892]
Traceback (most recent call last):
  File "c:\users\user\desktop\microblog\myenv\lib\site-packages\flask\app.py", line 2447, in wsgi_app
    response = self.full_dispatch_request()
  File "c:\users\user\desktop\microblog\myenv\lib\site-packages\flask\app.py", line 1952, in full_dispatch_request
    rv = self.handle_user_exception(e)
  File "c:\users\user\desktop\microblog\myenv\lib\site-packages\flask\app.py", line 1821, in handle_user_exception
    reraise(exc_type, exc_value, tb)
  File "c:\users\user\desktop\microblog\myenv\lib\site-packages\flask\_compat.py", line 39, in reraise
    raise value
  File "c:\users\user\desktop\microblog\myenv\lib\site-packages\flask\app.py", line 1950, in full_dispatch_request
    rv = self.dispatch_request()
  File "c:\users\user\desktop\microblog\myenv\lib\site-packages\flask\app.py", line 1936, in dispatch_request
    return self.view_functions[rule.endpoint](**req.view_args)
  File "C:\Users\User\Desktop\microblog\app\routes.py", line 28, in index
    posts = current_user.followed_posts().paginate(page, app.config['POSTS_PER_PAGE'], False)
  File "c:\users\user\desktop\microblog\myenv\lib\site-packages\werkzeug\local.py", line 347, in __getattr__
    return getattr(self._get_current_object(), name)
AttributeError: 'AnonymousUserMixin' object has no attribute 'followed_posts'
2021-02-06 14:50:35,539 INFO: Microblog startup [in C:\Users\User\Desktop\microblog\app\__init__.py:51]
2021-02-06 14:50:46,255 INFO: Microblog startup [in C:\Users\User\Desktop\microblog\app\__init__.py:51]
2021-02-06 14:51:24,038 INFO: Microblog startup [in C:\Users\User\Desktop\microblog\app\__init__.py:51]
2021-02-06 14:51:32,476 INFO: Microblog startup [in C:\Users\User\Desktop\microblog\app\__init__.py:51]
2021-02-06 14:51:41,389 INFO: Microblog startup [in C:\Users\User\Desktop\microblog\app\__init__.py:51]
2021-02-06 14:52:09,444 INFO: Microblog startup [in C:\Users\User\Desktop\microblog\app\__init__.py:51]
2021-02-06 14:52:57,304 INFO: Microblog startup [in C:\Users\User\Desktop\microblog\app\__init__.py:51]
2021-02-06 14:53:08,007 INFO: Microblog startup [in C:\Users\User\Desktop\microblog\app\__init__.py:51]
2021-02-06 14:53:20,631 INFO: Microblog startup [in C:\Users\User\Desktop\microblog\app\__init__.py:51]
2021-02-06 14:53:26,133 INFO: Microblog startup [in C:\Users\User\Desktop\microblog\app\__init__.py:51]
2021-02-06 14:54:57,217 INFO: Microblog startup [in C:\Users\User\Desktop\microblog\app\__init__.py:51]
2021-02-06 14:55:07,141 INFO: Microblog startup [in C:\Users\User\Desktop\microblog\app\__init__.py:51]
2021-02-06 14:56:35,445 INFO: Microblog startup [in C:\Users\User\Desktop\microblog\app\__init__.py:51]
2021-02-06 14:56:40,006 INFO: Microblog startup [in C:\Users\User\Desktop\microblog\app\__init__.py:51]
2021-02-06 14:57:38,614 INFO: Microblog startup [in C:\Users\User\Desktop\microblog\app\__init__.py:51]
2021-02-06 14:59:31,713 INFO: Microblog startup [in C:\Users\User\Desktop\microblog\app\__init__.py:51]
2021-02-06 15:00:01,132 INFO: Microblog startup [in C:\Users\User\Desktop\microblog\app\__init__.py:51]
2021-02-06 15:00:06,960 INFO: Microblog startup [in C:\Users\User\Desktop\microblog\app\__init__.py:51]
2021-02-06 15:00:31,913 INFO: Microblog startup [in C:\Users\User\Desktop\microblog\app\__init__.py:51]
2021-02-06 15:00:36,320 ERROR: Exception on /index [GET] [in c:\users\user\desktop\microblog\myenv\lib\site-packages\flask\app.py:1892]
Traceback (most recent call last):
  File "c:\users\user\desktop\microblog\myenv\lib\site-packages\flask\app.py", line 2447, in wsgi_app
    response = self.full_dispatch_request()
  File "c:\users\user\desktop\microblog\myenv\lib\site-packages\flask\app.py", line 1952, in full_dispatch_request
    rv = self.handle_user_exception(e)
  File "c:\users\user\desktop\microblog\myenv\lib\site-packages\flask\app.py", line 1821, in handle_user_exception
    reraise(exc_type, exc_value, tb)
  File "c:\users\user\desktop\microblog\myenv\lib\site-packages\flask\_compat.py", line 39, in reraise
    raise value
  File "c:\users\user\desktop\microblog\myenv\lib\site-packages\flask\app.py", line 1950, in full_dispatch_request
    rv = self.dispatch_request()
  File "c:\users\user\desktop\microblog\myenv\lib\site-packages\flask\app.py", line 1936, in dispatch_request
    return self.view_functions[rule.endpoint](**req.view_args)
  File "C:\Users\User\Desktop\microblog\app\routes.py", line 28, in index
    posts = current_user.followed_posts().paginate(page, app.config['POSTS_PER_PAGE'], False)
  File "c:\users\user\desktop\microblog\myenv\lib\site-packages\werkzeug\local.py", line 347, in __getattr__
    return getattr(self._get_current_object(), name)
AttributeError: 'AnonymousUserMixin' object has no attribute 'followed_posts'
2021-02-06 15:03:36,180 INFO: Microblog startup [in C:\Users\User\Desktop\microblog\app\__init__.py:51]
2021-02-06 15:03:41,592 ERROR: Exception on / [GET] [in c:\users\user\desktop\microblog\myenv\lib\site-packages\flask\app.py:1892]
Traceback (most recent call last):
  File "c:\users\user\desktop\microblog\myenv\lib\site-packages\flask\app.py", line 2447, in wsgi_app
    response = self.full_dispatch_request()
  File "c:\users\user\desktop\microblog\myenv\lib\site-packages\flask\app.py", line 1952, in full_dispatch_request
    rv = self.handle_user_exception(e)
  File "c:\users\user\desktop\microblog\myenv\lib\site-packages\flask\app.py", line 1821, in handle_user_exception
    reraise(exc_type, exc_value, tb)
  File "c:\users\user\desktop\microblog\myenv\lib\site-packages\flask\_compat.py", line 39, in reraise
    raise value
  File "c:\users\user\desktop\microblog\myenv\lib\site-packages\flask\app.py", line 1950, in full_dispatch_request
    rv = self.dispatch_request()
  File "c:\users\user\desktop\microblog\myenv\lib\site-packages\flask\app.py", line 1936, in dispatch_request
    return self.view_functions[rule.endpoint](**req.view_args)
  File "C:\Users\User\Desktop\microblog\app\routes.py", line 28, in index
    pos = current_user.followed_posts()
  File "c:\users\user\desktop\microblog\myenv\lib\site-packages\werkzeug\local.py", line 347, in __getattr__
    return getattr(self._get_current_object(), name)
AttributeError: 'AnonymousUserMixin' object has no attribute 'followed_posts'
2021-02-06 15:03:43,385 ERROR: Exception on /index [GET] [in c:\users\user\desktop\microblog\myenv\lib\site-packages\flask\app.py:1892]
Traceback (most recent call last):
  File "c:\users\user\desktop\microblog\myenv\lib\site-packages\flask\app.py", line 2447, in wsgi_app
    response = self.full_dispatch_request()
  File "c:\users\user\desktop\microblog\myenv\lib\site-packages\flask\app.py", line 1952, in full_dispatch_request
    rv = self.handle_user_exception(e)
  File "c:\users\user\desktop\microblog\myenv\lib\site-packages\flask\app.py", line 1821, in handle_user_exception
    reraise(exc_type, exc_value, tb)
  File "c:\users\user\desktop\microblog\myenv\lib\site-packages\flask\_compat.py", line 39, in reraise
    raise value
  File "c:\users\user\desktop\microblog\myenv\lib\site-packages\flask\app.py", line 1950, in full_dispatch_request
    rv = self.dispatch_request()
  File "c:\users\user\desktop\microblog\myenv\lib\site-packages\flask\app.py", line 1936, in dispatch_request
    return self.view_functions[rule.endpoint](**req.view_args)
  File "C:\Users\User\Desktop\microblog\app\routes.py", line 28, in index
    pos = current_user.followed_posts()
  File "c:\users\user\desktop\microblog\myenv\lib\site-packages\werkzeug\local.py", line 347, in __getattr__
    return getattr(self._get_current_object(), name)
AttributeError: 'AnonymousUserMixin' object has no attribute 'followed_posts'
2021-02-06 15:04:23,617 INFO: Microblog startup [in C:\Users\User\Desktop\microblog\app\__init__.py:51]
2021-02-06 15:05:59,704 INFO: Microblog startup [in C:\Users\User\Desktop\microblog\app\__init__.py:51]
2021-02-06 15:12:06,645 INFO: Microblog startup [in C:\Users\User\Desktop\microblog\app\__init__.py:53]
2021-02-06 15:13:52,116 INFO: Microblog startup [in C:\Users\User\Desktop\microblog\app\__init__.py:53]
